Workbook

Sheet 峰谷误差
A2: 原估算与 Rocky：逐圈波峰、波谷误差
A4: 对比第1–86个完整循环。误差以参考文件为分母；第87–100圈保留估算值，误差留空。
A6: 统计指标 | B6: 波峰 | C6: 波谷 | D6: 统计口径
A7: 平均绝对相对误差 | B7: =AVERAGE(G36:G135) -> 0.23326542 | C7: =AVERAGE(M36:M135) -> 0.17849954 | D7: MAPE；波谷首圈为0分母，不计入百分比平均
A8: 平均绝对误差 (mm) | B8: =AVERAGE(E36:E135) -> 0.73799557 | C8: =AVERAGE(K36:K135) -> 0.38086132 | D8: MAE；86个完整循环均计入
A9: 均方根误差 (mm) | B9: =SQRT(SUMSQ(D36:D135)/COUNT(D36:D135)) -> 0.74288522 | C9: =SQRT(SUMSQ(J36:J135)/COUNT(J36:J135)) -> 0.39087898 | D9: RMSE；86个完整循环均计入
A10: 平均偏差 (mm) | B10: =AVERAGE(D36:D135) -> -0.73799557 | C10: =AVERAGE(J36:J135) -> -0.38086132 | D10: 估算减参考；负值表示估算偏低
A11: 百分比有效循环数 | B11: =COUNT(G36:G135) -> 86 | C11: =COUNT(M36:M135) -> 85 | D11: 未把缺少完整参考数据的循环视为零误差
A13: 有符号相对误差 = (估算 - 参考) / 参考；绝对相对误差 = |估算 - 参考| / |参考|。
A14: 参考波峰/波谷取自原文件循环汇总；估算由原模型快照的0.02 s时程求极值，没有重新拟合。
A35: 循环 N | B35: 参考波峰 (mm) | C35: 估算波峰 (mm) | D35: 波峰差值 (mm) | E35: 波峰绝对差 (mm) | F35: 波峰相对误差 | G35: 波峰绝对相对误差 | H35: 参考波谷 (mm) | I35: 估算波谷 (mm) | J35: 波谷差值 (mm) | K35: 波谷绝对差 (mm) | L35: 波谷相对误差 | M35: 波谷绝对相对误差 | N35: 比较状态
A36: 1 | B36: =IF(COUNTIFS(参考循环数据!$A$7:$A$92,A36)>0,VLOOKUP(A36,参考循环数据!$A$7:$I$92,6,FALSE),"") -> 2.2239786 | C36: =MAX('0.02s时程'!G2:G67) -> 1.3068722 | D36: =IF(ISNUMBER(B36),C36-B36,"") -> -0.91710634 | E36: =IF(ISNUMBER(D36),ABS(D36),"") -> 0.91710634 | F36: =IF(ISNUMBER(B36),IF(B36=0,"不适用（参考为0）",D36/B36),"") -> -0.41237193 | G36: =IF(ISNUMBER(F36),ABS(F36),F36) -> 0.41237193 | H36: =IF(COUNTIFS(参考循环数据!$A$7:$A$92,A36)>0,VLOOKUP(A36,参考循环数据!$A$7:$I$92,5,FALSE),"") -> 0 | I36: =MIN('0.02s时程'!G2:G67) -> 0 | J36: =IF(ISNUMBER(H36),I36-H36,"") -> 0 | K36: =IF(ISNUMBER(J36),ABS(J36),"") -> 0 | L36: =IF(ISNUMBER(H36),IF(H36=0,"不适用（参考为0）",J36/H36),"") -> 不适用（参考为0） | M36: =IF(ISNUMBER(L36),ABS(L36),L36) -> 不适用（参考为0） | N36: 完整参考循环
A37: 2 | B37: =IF(COUNTIFS(参考循环数据!$A$7:$A$92,A37)>0,VLOOKUP(A37,参考循环数据!$A$7:$I$92,6,FALSE),"") -> 2.3544004 | C37: =MAX('0.02s时程'!G67:G132) -> 1.4773362 | D37: =IF(ISNUMBER(B37),C37-B37,"") -> -0.87706423 | E37: =IF(ISNUMBER(D37),ABS(D37),"") -> 0.87706423 | F37: =IF(ISNUMBER(B37),IF(B37=0,"不适用（参考为0）",D37/B37),"") -> -0.37252127 | G37: =IF(ISNUMBER(F37),ABS(F37),F37) -> 0.37252127 | H37: =IF(COUNTIFS(参考循环数据!$A$7:$A$92,A37)>0,VLOOKUP(A37,参考循环数据!$A$7:$I$92,5,FALSE),"") -> 1.3364279 | I37: =MIN('0.02s时程'!G67:G132) -> 0.73150958 | J37: =IF(ISNUMBER(H37),I37-H37,"") -> -0.60491836 | K37: =IF(ISNUMBER(J37),ABS(J37),"") -> 0.60491836 | L37: =IF(ISNUMBER(H37),IF(H37=0,"不适用（参考为0）",J37/H37),"") -> -0.45263822 | M37: =IF(ISNUMBER(L37),ABS(L37),L37) -> 0.45263822 | N37: 完整参考循环
A38: 3 | B38: =IF(COUNTIFS(参考循环数据!$A$7:$A$92,A38)>0,VLOOKUP(A38,参考循环数据!$A$7:$I$92,6,FALSE),"") -> 2.4453973 | C38: =MAX('0.02s时程'!G132:G197) -> 1.5918643 | D38: =IF(ISNUMBER(B38),C38-B38,"") -> -0.85353293 | E38: =IF(ISNUMBER(D38),ABS(D38),"") -> 0.85353293 | F38: =IF(ISNUMBER(B38),IF(B38=0,"不适用（参考为0）",D38/B38),"") -> -0.34903651 | G38: =IF(ISNUMBER(F38),ABS(F38),F38) -> 0.34903651 | H38: =IF(COUNTIFS(参考循环数据!$A$7:$A$92,A38)>0,VLOOKUP(A38,参考循环数据!$A$7:$I$92,5,FALSE),"") -> 1.4531613 | I38: =MIN('0.02s时程'!G132:G197) -> 0.88220817 | J38: =IF(ISNUMBER(H38),I38-H38,"") -> -0.57095308 | K38: =IF(ISNUMBER(J38),ABS(J38),"") -> 0.57095308 | L38: =IF(ISNUMBER(H38),IF(H38=0,"不适用（参考为0）",J38/H38),"") -> -0.39290415 | M38: =IF(ISNUMBER(L38),ABS(L38),L38) -> 0.39290415 | N38: 完整参考循环
A39: 4 | B39: =IF(COUNTIFS(参考循环数据!$A$7:$A$92,A39)>0,VLOOKUP(A39,参考循环数据!$A$7:$I$92,6,FALSE),"") -> 2.5159427 | C39: =MAX('0.02s时程'!G197:G262) -> 1.6805391 | D39: =IF(ISNUMBER(B39),C39-B39,"") -> -0.83540362 | E39: =IF(ISNUMBER(D39),ABS(D39),"") -> 0.83540362 | F39: =IF(ISNUMBER(B39),IF(B39=0,"不适用（参考为0）",D39/B39),"") -> -0.33204397 | G39: =IF(ISNUMBER(F39),ABS(F39),F39) -> 0.33204397 | H39: =IF(COUNTIFS(参考循环数据!$A$7:$A$92,A39)>0,VLOOKUP(A39,参考循环数据!$A$7:$I$92,5,FALSE),"") -> 1.5326778 | I39: =MIN('0.02s时程'!G197:G262) -> 0.98874032 | J39: =IF(ISNUMBER(H39),I39-H39,"") -> -0.54393753 | K39: =IF(ISNUMBER(J39),ABS(J39),"") -> 0.54393753 | L39: =IF(ISNUMBER(H39),IF(H39=0,"不适用（参考为0）",J39/H39),"") -> -0.35489358 | M39: =IF(ISNUMBER(L39),ABS(L39),L39) -> 0.35489358 | N39: 完整参考循环
A40: 5 | B40: =IF(COUNTIFS(参考循环数据!$A$7:$A$92,A40)>0,VLOOKUP(A40,参考循环数据!$A$7:$I$92,6,FALSE),"") -> 2.5719775 | C40: =MAX('0.02s时程'!G262:G327) -> 1.7536001 | D40: =IF(ISNUMBER(B40),C40-B40,"") -> -0.81837739 | E40: =IF(ISNUMBER(D40),ABS(D40),"") -> 0.81837739 | F40: =IF(ISNUMBER(B40),IF(B40=0,"不适用（参考为0）",D40/B40),"") -> -0.31818995 | G40: =IF(ISNUMBER(F40),ABS(F40),F40) -> 0.31818995 | H40: =IF(COUNTIFS(参考循环数据!$A$7:$A$92,A40)>0,VLOOKUP(A40,参考循环数据!$A$7:$I$92,5,FALSE),"") -> 1.5938789 | I40: =MIN('0.02s时程'!G262:G327) -> 1.0728525 | J40: =IF(ISNUMBER(H40),I40-H40,"") -> -0.5210264 | K40: =IF(ISNUMBER(J40),ABS(J40),"") -> 0.5210264 | L40: =IF(ISNUMBER(H40),IF(H40=0,"不适用（参考为0）",J40/H40),"") -> -0.3268921 | M40: =IF(ISNUMBER(L40),ABS(L40),L40) -> 0.3268921 | N40: 完整参考循环
A41: 6 | B41: =IF(COUNTIFS(参考循环数据!$A$7:$A$92,A41)>0,VLOOKUP(A41,参考循环数据!$A$7:$I$92,6,FALSE),"") -> 2.6149734 | C41: =MAX('0.02s时程'!G327:G392) -> 1.8159914 | D41: =IF(ISNUMBER(B41),C41-B41,"") -> -0.79898198 | E41: =IF(ISNUMBER(D41),ABS(D41),"") -> 0.79898198 | F41: =IF(ISNUMBER(B41),IF(B41=0,"不适用（参考为0）",D41/B41),"") -> -0.30554115 | G41: =IF(ISNUMBER(F41),ABS(F41),F41) -> 0.30554115 | H41: =IF(COUNTIFS(参考循环数据!$A$7:$A$92,A41)>0,VLOOKUP(A41,参考循环数据!$A$7:$I$92,5,FALSE),"") -> 1.6392043 | I41: =MIN('0.02s时程'!G327:G392) -> 1.142894 | J41: =IF(ISNUMBER(H41),I41-H41,"") -> -0.49631028 | K41: =IF(ISNUMBER(J41),ABS(J41),"") -> 0.49631028 | L41: =IF(ISNUMBER(H41),IF(H41=0,"不适用（参考为0）",J41/H41),"") -> -0.30277512 | M41: =IF(ISNUMBER(L41),ABS(L41),L41) -> 0.30277512 | N41: 完整参考循环
A42: 7 | B42: =IF(COUNTIFS(参考循环数据!$A$7:$A$92,A42)>0,VLOOKUP(A42,参考循环数据!$A$7:$I$92,6,FALSE),"") -> 2.6534431 | C42: =MAX('0.02s时程'!G392:G457) -> 1.8705401 | D42: =IF(ISNUMBER(B42),C42-B42,"") -> -0.78290295 | E42: =IF(ISNUMBER(D42),ABS(D42),"") -> 0.78290295 | F42: =IF(ISNUMBER(B42),IF(B42=0,"不适用（参考为0）",D42/B42),"") -> -0.29505172 | G42: =IF(ISNUMBER(F42),ABS(F42),F42) -> 0.29505172 | H42: =IF(COUNTIFS(参考循环数据!$A$7:$A$92,A42)>0,VLOOKUP(A42,参考循环数据!$A$7:$I$92,5,FALSE),"") -> 1.6762613 | I42: =MIN('0.02s时程'!G392:G457) -> 1.2031116 | J42: =IF(ISNUMBER(H42),I42-H42,"") -> -0.47314973 | K42: =IF(ISNUMBER(J42),ABS(J42),"") -> 0.47314973 | L42: =IF(ISNUMBER(H42),IF(H42=0,"不适用（参考为0）",J42/H42),"") -> -0.2822649 | M42: =IF(ISNUMBER(L42),ABS(L42),L42) -> 0.2822649 | N42: 完整参考循环
A43: 8 | B43: =IF(COUNTIFS(参考循环数据!$A$7:$A$92,A43)>0,VLOOKUP(A43,参考循环数据!$A$7:$I$92,6,FALSE),"") -> 2.6841355 | C43: =MAX('0.02s时程'!G457:G522) -> 1.9190377 | D43: =IF(ISNUMBER(B43),C43-B43,"") -> -0.76509786 | E43: =IF(ISNUMBER(D43),ABS(D43),"") -> 0.76509786 | F43: =IF(ISNUMBER(B43),IF(B43=0,"不适用（参考为0）",D43/B43),"") -> -0.28504442 | G43: =IF(ISNUMBER(F43),ABS(F43),F43) -> 0.28504442 | H43: =IF(COUNTIFS(参考循环数据!$A$7:$A$92,A43)>0,VLOOKUP(A43,参考循环数据!$A$7:$I$92,5,FALSE),"") -> 1.7087247 | I43: =MIN('0.02s时程'!G457:G522) -> 1.2560074 | J43: =IF(ISNUMBER(H43),I43-H43,"") -> -0.45271739 | K43: =IF(ISNUMBER(J43),ABS(J43),"") -> 0.45271739 | L43: =IF(ISNUMBER(H43),IF(H43=0,"不适用（参考为0）",J43/H43),"") -> -0.2649446 | M43: =IF(ISNUMBER(L43),ABS(L43),L43) -> 0.2649446 | N43: 完整参考循环
A44: 9 | B44: =IF(COUNTIFS(参考循环数据!$A$7:$A$92,A44)>0,VLOOKUP(A44,参考循环数据!$A$7:$I$92,6,FALSE),"") -> 2.7134724 | C44: =MAX('0.02s时程'!G522:G587) -> 1.9627014 | D44: =IF(ISNUMBER(B44),C44-B44,"") -> -0.75077096 | E44: =IF(ISNUMBER(D44),ABS(D44),"") -> 0.75077096 | F44: =IF(ISNUMBER(B44),IF(B44=0,"不适用（参考为0）",D44/B44),"") -> -0.27668273 | G44: =IF(ISNUMBER(F44),ABS(F44),F44) -> 0.27668273 | H44: =IF(COUNTIFS(参考循环数据!$A$7:$A$92,A44)>0,VLOOKUP(A44,参考循环数据!$A$7:$I$92,5,FALSE),"") -> 1.7378688 | I44: =MIN('0.02s时程'!G522:G587) -> 1.3031987 | J44: =IF(ISNUMBER(H44),I44-H44,"") -> -0.43467007 | K44: =IF(ISNUMBER(J44),ABS(J44),"") -> 0.43467007 | L44: =IF(ISNUMBER(H44),IF(H44=0,"不适用（参考为0）",J44/H44),"") -> -0.25011674 | M44: =IF(ISNUMBER(L44),ABS(L44),L44) -> 0.25011674 | N44: 完整参考循环
A45: 10 | B45: =IF(COUNTIFS(参考循环数据!$A$7:$A$92,A45)>0,VLOOKUP(A45,参考循环数据!$A$7:$I$92,6,FALSE),"") -> 2.7395907 | C45: =MAX('0.02s时程'!G587:G652) -> 2.0024015 | D45: =IF(ISNUMBER(B45),C45-B45,"") -> -0.73718917 | E45: =IF(ISNUMBER(D45),ABS(D45),"") -> 0.73718917 | F45: =IF(ISNUMBER(B45),IF(B45=0,"不适用（参考为0）",D45/B45),"") -> -0.26908734 | G45: =IF(ISNUMBER(F45),ABS(F45),F45) -> 0.26908734 | H45: =IF(COUNTIFS(参考循环数据!$A$7:$A$92,A45)>0,VLOOKUP(A45,参考循环数据!$A$7:$I$92,5,FALSE),"") -> 1.7643067 | I45: =MIN('0.02s时程'!G587:G652) -> 1.3458003 | J45: =IF(ISNUMBER(H45),I45-H45,"") -> -0.41850641 | K45: =IF(ISNUMBER(J45),ABS(J45),"") -> 0.41850641 | L45: =IF(ISNUMBER(H45),IF(H45=0,"不适用（参考为0）",J45/H45),"") -> -0.23720729 | M45: =IF(ISNUMBER(L45),ABS(L45),L45) -> 0.23720729 | N45: 完整参考循环
A46: 11 | B46: =IF(COUNTIFS(参考循环数据!$A$7:$A$92,A46)>0,VLOOKUP(A46,参考循环数据!$A$7:$I$92,6,FALSE),"") -> 2.7664592 | C46: =MAX('0.02s时程'!G652:G717) -> 2.0387844 | D46: =IF(ISNUMBER(B46),C46-B46,"") -> -0.72767472 | E46: =IF(ISNUMBER(D46),ABS(D46),"") -> 0.72767472 | F46: =IF(ISNUMBER(B46),IF(B46=0,"不适用（参考为0）",D46/B46),"") -> -0.26303469 | G46: =IF(ISNUMBER(F46),ABS(F46),F46) -> 0.26303469 | H46: =IF(COUNTIFS(参考循环数据!$A$7:$A$92,A46)>0,VLOOKUP(A46,参考循环数据!$A$7:$I$92,5,FALSE),"") -> 1.7884987 | I46: =MIN('0.02s时程'!G652:G717) -> 1.3846174 | J46: =IF(ISNUMBER(H46),I46-H46,"") -> -0.40388137 | K46: =IF(ISNUMBER(J46),ABS(J46),"") -> 0.40388137 | L46: =IF(ISNUMBER(H46),IF(H46=0,"不适用（参考为0）",J46/H46),"") -> -0.22582145 | M46: =IF(ISNUMBER(L46),ABS(L46),L46) -> 0.22582145 | N46: 完整参考循环
A47: 12 | B47: =IF(COUNTIFS(参考循环数据!$A$7:$A$92,A47)>0,VLOOKUP(A47,参考循环数据!$A$7:$I$92,6,FALSE),"") -> 2.7909798 | C47: =MAX('0.02s时程'!G717:G782) -> 2.0723454 | D47: =IF(ISNUMBER(B47),C47-B47,"") -> -0.71863445 | E47: =IF(ISNUMBER(D47),ABS(D47),"") -> 0.71863445 | F47: =IF(ISNUMBER(B47),IF(B47=0,"不适用（参考为0）",D47/B47),"") -> -0.25748464 | G47: =IF(ISNUMBER(F47),ABS(F47),F47) -> 0.25748464 | H47: =IF(COUNTIFS(参考循环数据!$A$7:$A$92,A47)>0,VLOOKUP(A47,参考循环数据!$A$7:$I$92,5,FALSE),"") -> 1.8141852 | I47: =MIN('0.02s时程'!G717:G782) -> 1.4202531 | J47: =IF(ISNUMBER(H47),I47-H47,"") -> -0.39393209 | K47: =IF(ISNUMBER(J47),ABS(J47),"") -> 0.39393209 | L47: =IF(ISNUMBER(H47),IF(H47=0,"不适用（参考为0）",J47/H47),"") -> -0.21713995 | M47: =IF(ISNUMBER(L47),ABS(L47),L47) -> 0.21713995 | N47: 完整参考循环
A48: 13 | B48: =IF(COUNTIFS(参考循环数据!$A$7:$A$92,A48)>0,VLOOKUP(A48,参考循环数据!$A$7:$I$92,6,FALSE),"") -> 2.8150501 | C48: =MAX('0.02s时程'!G782:G847) -> 2.103473 | D48: =IF(ISNUMBER(B48),C48-B48,"") -> -0.71157712 | E48: =IF(ISNUMBER(D48),ABS(D48),"") -> 0.71157712 | F48: =IF(ISNUMBER(B48),IF(B48=0,"不适用（参考为0）",D48/B48),"") -> -0.25277601 | G48: =IF(ISNUMBER(F48),ABS(F48),F48) -> 0.25277601 | H48: =IF(COUNTIFS(参考循环数据!$A$7:$A$92,A48)>0,VLOOKUP(A48,参考循环数据!$A$7:$I$92,5,FALSE),"") -> 1.8362418 | I48: =MIN('0.02s时程'!G782:G847) -> 1.4531727 | J48: =IF(ISNUMBER(H48),I48-H48,"") -> -0.38306909 | K48: =IF(ISNUMBER(J48),ABS(J48),"") -> 0.38306909 | L48: =IF(ISNUMBER(H48),IF(H48=0,"不适用（参考为0）",J48/H48),"") -> -0.20861582 | M48: =IF(ISNUMBER(L48),ABS(L48),L48) -> 0.20861582 | N48: 完整参考循环
A49: 14 | B49: =IF(COUNTIFS(参考循环数据!$A$7:$A$92,A49)>0,VLOOKUP(A49,参考循环数据!$A$7:$I$92,6,FALSE),"") -> 2.8343292 | C49: =MAX('0.02s时程'!G847:G912) -> 2.1324786 | D49: =IF(ISNUMBER(B49),C49-B49,"") -> -0.70185057 | E49: =IF(ISNUMBER(D49),ABS(D49),"") -> 0.70185057 | F49: =IF(ISNUMBER(B49),IF(B49=0,"不适用（参考为0）",D49/B49),"") -> -0.24762493 | G49: =IF(ISNUMBER(F49),ABS(F49),F49) -> 0.24762493 | H49: =IF(COUNTIFS(参考循环数据!$A$7:$A$92,A49)>0,VLOOKUP(A49,参考循环数据!$A$7:$I$92,5,FALSE),"") -> 1.8544966 | I49: =MIN('0.02s时程'!G847:G912) -> 1.4837432 | J49: =IF(ISNUMBER(H49),I49-H49,"") -> -0.3707534 | K49: =IF(ISNUMBER(J49),ABS(J49),"") -> 0.3707534 | L49: =IF(ISNUMBER(H49),IF(H49=0,"不适用（参考为0）",J49/H49),"") -> -0.19992132 | M49: =IF(ISNUMBER(L49),ABS(L49),L49) -> 0.19992132 | N49: 完整参考循环
A50: 15 | B50: =IF(COUNTIFS(参考循环数据!$A$7:$A$92,A50)>0,VLOOKUP(A50,参考循环数据!$A$7:$I$92,6,FALSE),"") -> 2.8504851 | C50: =MAX('0.02s时程'!G912:G977) -> 2.159616 | D50: =IF(ISNUMBER(B50),C50-B50,"") -> -0.69086904 | E50: =IF(ISNUMBER(D50),ABS(D50),"") -> 0.69086904 | F50: =IF(ISNUMBER(B50),IF(B50=0,"不适用（参考为0）",D50/B50),"") -> -0.24236894 | G50: =IF(ISNUMBER(F50),ABS(F50),F50) -> 0.24236894 | H50: =IF(COUNTIFS(参考循环数据!$A$7:$A$92,A50)>0,VLOOKUP(A50,参考循环数据!$A$7:$I$92,5,FALSE),"") -> 1.8713365 | I50: =MIN('0.02s时程'!G912:G977) -> 1.5122599 | J50: =IF(ISNUMBER(H50),I50-H50,"") -> -0.35907654 | K50: =IF(ISNUMBER(J50),ABS(J50),"") -> 0.35907654 | L50: =IF(ISNUMBER(H50),IF(H50=0,"不适用（参考为0）",J50/H50),"") -> -0.1918824 | M50: =IF(ISNUMBER(L50),ABS(L50),L50) -> 0.1918824 | N50: 完整参考循环
A51: 16 | B51: =IF(COUNTIFS(参考循环数据!$A$7:$A$92,A51)>0,VLOOKUP(A51,参考循环数据!$A$7:$I$92,6,FALSE),"") -> 2.8683936 | C51: =MAX('0.02s时程'!G977:G1042) -> 2.185095 | D51: =IF(ISNUMBER(B51),C51-B51,"") -> -0.68329868 | E51: =IF(ISNUMBER(D51),ABS(D51),"") -> 0.68329868 | F51: =IF(ISNUMBER(B51),IF(B51=0,"不适用（参考为0）",D51/B51),"") -> -0.2382165 | G51: =IF(ISNUMBER(F51),ABS(F51),F51) -> 0.2382165 | H51: =IF(COUNTIFS(参考循环数据!$A$7:$A$92,A51)>0,VLOOKUP(A51,参考循环数据!$A$7:$I$92,5,FALSE),"") -> 1.8871786 | I51: =MIN('0.02s时程'!G977:G1042) -> 1.5389645 | J51: =IF(ISNUMBER(H51),I51-H51,"") -> -0.34821413 | K51: =IF(ISNUMBER(J51),ABS(J51),"") -> 0.34821413 | L51: =IF(ISNUMBER(H51),IF(H51=0,"不适用（参考为0）",J51/H51),"") -> -0.18451572 | M51: =IF(ISNUMBER(L51),ABS(L51),L51) -> 0.18451572 | N51: 完整参考循环
A52: 17 | B52: =IF(COUNTIFS(参考循环数据!$A$7:$A$92,A52)>0,VLOOKUP(A52,参考循环数据!$A$7:$I$92,6,FALSE),"") -> 2.8819375 | C52: =MAX('0.02s时程'!G1042:G1107) -> 2.2090911 | D52: =IF(ISNUMBER(B52),C52-B52,"") -> -0.67284644 | E52: =IF(ISNUMBER(D52),ABS(D52),"") -> 0.67284644 | F52: =IF(ISNUMBER(B52),IF(B52=0,"不适用（参考为0）",D52/B52),"") -> -0.23347017 | G52: =IF(ISNUMBER(F52),ABS(F52),F52) -> 0.23347017 | H52: =IF(COUNTIFS(参考循环数据!$A$7:$A$92,A52)>0,VLOOKUP(A52,参考循环数据!$A$7:$I$92,5,FALSE),"") -> 1.9036032 | I52: =MIN('0.02s时程'!G1042:G1107) -> 1.5640574 | J52: =IF(ISNUMBER(H52),I52-H52,"") -> -0.33954577 | K52: =IF(ISNUMBER(J52),ABS(J52),"") -> 0.33954577 | L52: =IF(ISNUMBER(H52),IF(H52=0,"不适用（参考为0）",J52/H52),"") -> -0.17837003 | M52: =IF(ISNUMBER(L52),ABS(L52),L52) -> 0.17837003 | N52: 完整参考循环
A53: 18 | B53: =IF(COUNTIFS(参考循环数据!$A$7:$A$92,A53)>0,VLOOKUP(A53,参考循环数据!$A$7:$I$92,6,FALSE),"") -> 2.8991907 | C53: =MAX('0.02s时程'!G1107:G1172) -> 2.231753 | D53: =IF(ISNUMBER(B53),C53-B53,"") -> -0.66743774 | E53: =IF(ISNUMBER(D53),ABS(D53),"") -> 0.66743774 | F53: =IF(ISNUMBER(B53),IF(B53=0,"不适用（参考为0）",D53/B53),"") -> -0.23021519 | G53: =IF(ISNUMBER(F53),ABS(F53),F53) -> 0.23021519 | H53: =IF(COUNTIFS(参考循环数据!$A$7:$A$92,A53)>0,VLOOKUP(A53,参考循环数据!$A$7:$I$92,5,FALSE),"") -> 1.9199382 | I53: =MIN('0.02s时程'!G1107:G1172) -> 1.587707 | J53: =IF(ISNUMBER(H53),I53-H53,"") -> -0.33223126 | K53: =IF(ISNUMBER(J53),ABS(J53),"") -> 0.33223126 | L53: =IF(ISNUMBER(H53),IF(H53=0,"不适用（参考为0）",J53/H53),"") -> -0.17304268 | M53: =IF(ISNUMBER(L53),ABS(L53),L53) -> 0.17304268 | N53: 完整参考循环
A54: 19 | B54: =IF(COUNTIFS(参考循环数据!$A$7:$A$92,A54)>0,VLOOKUP(A54,参考循环数据!$A$7:$I$92,6,FALSE),"") -> 2.9138851 | C54: =MAX('0.02s时程'!G1172:G1237) -> 2.2532078 | D54: =IF(ISNUMBER(B54),C54-B54,"") -> -0.66067728 | E54: =IF(ISNUMBER(D54),ABS(D54),"") -> 0.66067728 | F54: =IF(ISNUMBER(B54),IF(B54=0,"不适用（参考为0）",D54/B54),"") -> -0.22673416 | G54: =IF(ISNUMBER(F54),ABS(F54),F54) -> 0.22673416 | H54: =IF(COUNTIFS(参考循环数据!$A$7:$A$92,A54)>0,VLOOKUP(A54,参考循环数据!$A$7:$I$92,5,FALSE),"") -> 1.9362163 | I54: =MIN('0.02s时程'!G1172:G1237) -> 1.6100559 | J54: =IF(ISNUMBER(H54),I54-H54,"") -> -0.32616035 | K54: =IF(ISNUMBER(J54),ABS(J54),"") -> 0.32616035 | L54: =IF(ISNUMBER(H54),IF(H54=0,"不适用（参考为0）",J54/H54),"") -> -0.16845244 | M54: =IF(ISNUMBER(L54),ABS(L54),L54) -> 0.16845244 | N54: 完整参考循环
A55: 20 | B55: =IF(COUNTIFS(参考循环数据!$A$7:$A$92,A55)>0,VLOOKUP(A55,参考循环数据!$A$7:$I$92,6,FALSE),"") -> 2.9309916 | C55: =MAX('0.02s时程'!G1237:G1302) -> 2.273565 | D55: =IF(ISNUMBER(B55),C55-B55,"") -> -0.65742659 | E55: =IF(ISNUMBER(D55),ABS(D55),"") -> 0.65742659 | F55: =IF(ISNUMBER(B55),IF(B55=0,"不适用（参考为0）",D55/B55),"") -> -0.22430177 | G55: =IF(ISNUMBER(F55),ABS(F55),F55) -> 0.22430177 | H55: =IF(COUNTIFS(参考循环数据!$A$7:$A$92,A55)>0,VLOOKUP(A55,参考循环数据!$A$7:$I$92,5,FALSE),"") -> 1.9525233 | I55: =MIN('0.02s时程'!G1237:G1302) -> 1.6312267 | J55: =IF(ISNUMBER(H55),I55-H55,"") -> -0.32129665 | K55: =IF(ISNUMBER(J55),ABS(J55),"") -> 0.32129665 | L55: =IF(ISNUMBER(H55),IF(H55=0,"不适用（参考为0）",J55/H55),"") -> -0.16455458 | M55: =IF(ISNUMBER(L55),ABS(L55),L55) -> 0.16455458 | N55: 完整参考循环
A56: 21 | B56: =IF(COUNTIFS(参考循环数据!$A$7:$A$92,A56)>0,VLOOKUP(A56,参考循环数据!$A$7:$I$92,6,FALSE),"") -> 2.9475628 | C56: =MAX('0.02s时程'!G1302:G1367) -> 2.2929198 | D56: =IF(ISNUMBER(B56),C56-B56,"") -> -0.65464304 | E56: =IF(ISNUMBER(D56),ABS(D56),"") -> 0.65464304 | F56: =IF(ISNUMBER(B56),IF(B56=0,"不适用（参考为0）",D56/B56),"") -> -0.22209638 | G56: =IF(ISNUMBER(F56),ABS(F56),F56) -> 0.22209638 | H56: =IF(COUNTIFS(参考循环数据!$A$7:$A$92,A56)>0,VLOOKUP(A56,参考循环数据!$A$7:$I$92,5,FALSE),"") -> 1.9681848 | I56: =MIN('0.02s时程'!G1302:G1367) -> 1.6513249 | J56: =IF(ISNUMBER(H56),I56-H56,"") -> -0.31685989 | K56: =IF(ISNUMBER(J56),ABS(J56),"") -> 0.31685989 | L56: =IF(ISNUMBER(H56),IF(H56=0,"不适用（参考为0）",J56/H56),"") -> -0.16099093 | M56: =IF(ISNUMBER(L56),ABS(L56),L56) -> 0.16099093 | N56: 完整参考循环
A57: 22 | B57: =IF(COUNTIFS(参考循环数据!$A$7:$A$92,A57)>0,VLOOKUP(A57,参考循环数据!$A$7:$I$92,6,FALSE),"") -> 2.963029 | C57: =MAX('0.02s时程'!G1367:G1432) -> 2.3113553 | D57: =IF(ISNUMBER(B57),C57-B57,"") -> -0.65167369 | E57: =IF(ISNUMBER(D57),ABS(D57),"") -> 0.65167369 | F57: =IF(ISNUMBER(B57),IF(B57=0,"不适用（参考为0）",D57/B57),"") -> -0.21993497 | G57: =IF(ISNUMBER(F57),ABS(F57),F57) -> 0.21993497 | H57: =IF(COUNTIFS(参考循环数据!$A$7:$A$92,A57)>0,VLOOKUP(A57,参考循环数据!$A$7:$I$92,5,FALSE),"") -> 1.9835042 | I57: =MIN('0.02s时程'!G1367:G1432) -> 1.6704425 | J57: =IF(ISNUMBER(H57),I57-H57,"") -> -0.31306176 | K57: =IF(ISNUMBER(J57),ABS(J57),"") -> 0.31306176 | L57: =IF(ISNUMBER(H57),IF(H57=0,"不适用（参考为0）",J57/H57),"") -> -0.15783267 | M57: =IF(ISNUMBER(L57),ABS(L57),L57) -> 0.15783267 | N57: 完整参考循环
A58: 23 | B58: =IF(COUNTIFS(参考循环数据!$A$7:$A$92,A58)>0,VLOOKUP(A58,参考循环数据!$A$7:$I$92,6,FALSE),"") -> 2.9802096 | C58: =MAX('0.02s时程'!G1432:G1497) -> 2.3289447 | D58: =IF(ISNUMBER(B58),C58-B58,"") -> -0.65126485 | E58: =IF(ISNUMBER(D58),ABS(D58),"") -> 0.65126485 | F58: =IF(ISNUMBER(B58),IF(B58=0,"不适用（参考为0）",D58/B58),"") -> -0.21852988 | G58: =IF(ISNUMBER(F58),ABS(F58),F58) -> 0.21852988 | H58: =IF(COUNTIFS(参考循环数据!$A$7:$A$92,A58)>0,VLOOKUP(A58,参考循环数据!$A$7:$I$92,5,FALSE),"") -> 1.9990858 | I58: =MIN('0.02s时程'!G1432:G1497) -> 1.6886599 | J58: =IF(ISNUMBER(H58),I58-H58,"") -> -0.3104259 | K58: =IF(ISNUMBER(J58),ABS(J58),"") -> 0.3104259 | L58: =IF(ISNUMBER(H58),IF(H58=0,"不适用（参考为0）",J58/H58),"") -> -0.15528393 | M58: =IF(ISNUMBER(L58),ABS(L58),L58) -> 0.15528393 | N58: 完整参考循环
A59: 24 | B59: =IF(COUNTIFS(参考循环数据!$A$7:$A$92,A59)>0,VLOOKUP(A59,参考循环数据!$A$7:$I$92,6,FALSE),"") -> 2.9938116 | C59: =MAX('0.02s时程'!G1497:G1562) -> 2.3457529 | D59: =IF(ISNUMBER(B59),C59-B59,"") -> -0.64805868 | E59: =IF(ISNUMBER(D59),ABS(D59),"") -> 0.64805868 | F59: =IF(ISNUMBER(B59),IF(B59=0,"不适用（参考为0）",D59/B59),"") -> -0.21646609 | G59: =IF(ISNUMBER(F59),ABS(F59),F59) -> 0.21646609 | H59: =IF(COUNTIFS(参考循环数据!$A$7:$A$92,A59)>0,VLOOKUP(A59,参考循环数据!$A$7:$I$92,5,FALSE),"") -> 2.0138711 | I59: =MIN('0.02s时程'!G1497:G1562) -> 1.7060483 | J59: =IF(ISNUMBER(H59),I59-H59,"") -> -0.30782281 | K59: =IF(ISNUMBER(J59),ABS(J59),"") -> 0.30782281 | L59: =IF(ISNUMBER(H59),IF(H59=0,"不适用（参考为0）",J59/H59),"") -> -0.1528513 | M59: =IF(ISNUMBER(L59),ABS(L59),L59) -> 0.1528513 | N59: 完整参考循环
A60: 25 | B60: =IF(COUNTIFS(参考循环数据!$A$7:$A$92,A60)>0,VLOOKUP(A60,参考循环数据!$A$7:$I$92,6,FALSE),"") -> 3.0070541 | C60: =MAX('0.02s时程'!G1562:G1627) -> 2.3618374 | D60: =IF(ISNUMBER(B60),C60-B60,"") -> -0.64521667 | E60: =IF(ISNUMBER(D60),ABS(D60),"") -> 0.64521667 | F60: =IF(ISNUMBER(B60),IF(B60=0,"不适用（参考为0）",D60/B60),"") -> -0.2145677 | G60: =IF(ISNUMBER(F60),ABS(F60),F60) -> 0.2145677 | H60: =IF(COUNTIFS(参考循环数据!$A$7:$A$92,A60)>0,VLOOKUP(A60,参考循环数据!$A$7:$I$92,5,FALSE),"") -> 2.0273152 | I60: =MIN('0.02s时程'!G1562:G1627) -> 1.7226704 | J60: =IF(ISNUMBER(H60),I60-H60,"") -> -0.30464476 | K60: =IF(ISNUMBER(J60),ABS(J60),"") -> 0.30464476 | L60: =IF(ISNUMBER(H60),IF(H60=0,"不适用（参考为0）",J60/H60),"") -> -0.15027005 | M60: =IF(ISNUMBER(L60),ABS(L60),L60) -> 0.15027005 | N60: 完整参考循环
A61: 26 | B61: =IF(COUNTIFS(参考循环数据!$A$7:$A$92,A61)>0,VLOOKUP(A61,参考循环数据!$A$7:$I$92,6,FALSE),"") -> 3.0220809 | C61: =MAX('0.02s时程'!G1627:G1692) -> 2.3772498 | D61: =IF(ISNUMBER(B61),C61-B61,"") -> -0.64483113 | E61: =IF(ISNUMBER(D61),ABS(D61),"") -> 0.64483113 | F61: =IF(ISNUMBER(B61),IF(B61=0,"不适用（参考为0）",D61/B61),"") -> -0.21337322 | G61: =IF(ISNUMBER(F61),ABS(F61),F61) -> 0.21337322 | H61: =IF(COUNTIFS(参考循环数据!$A$7:$A$92,A61)>0,VLOOKUP(A61,参考循环数据!$A$7:$I$92,5,FALSE),"") -> 2.0401025 | I61: =MIN('0.02s时程'!G1627:G1692) -> 1.7385823 | J61: =IF(ISNUMBER(H61),I61-H61,"") -> -0.3015202 | K61: =IF(ISNUMBER(J61),ABS(J61),"") -> 0.3015202 | L61: =IF(ISNUMBER(H61),IF(H61=0,"不适用（参考为0）",J61/H61),"") -> -0.1477966 | M61: =IF(ISNUMBER(L61),ABS(L61),L61) -> 0.1477966 | N61: 完整参考循环
A62: 27 | B62: =IF(COUNTIFS(参考循环数据!$A$7:$A$92,A62)>0,VLOOKUP(A62,参考循环数据!$A$7:$I$92,6,FALSE),"") -> 3.0393578 | C62: =MAX('0.02s时程'!G1692:G1757) -> 2.3920362 | D62: =IF(ISNUMBER(B62),C62-B62,"") -> -0.64732167 | E62: =IF(ISNUMBER(D62),ABS(D62),"") -> 0.64732167 | F62: =IF(ISNUMBER(B62),IF(B62=0,"不适用（参考为0）",D62/B62),"") -> -0.21297975 | G62: =IF(ISNUMBER(F62),ABS(F62),F62) -> 0.21297975 | H62: =IF(COUNTIFS(参考循环数据!$A$7:$A$92,A62)>0,VLOOKUP(A62,参考循环数据!$A$7:$I$92,5,FALSE),"") -> 2.0529082 | I62: =MIN('0.02s时程'!G1692:G1757) -> 1.753834 | J62: =IF(ISNUMBER(H62),I62-H62,"") -> -0.29907418 | K62: =IF(ISNUMBER(J62),ABS(J62),"") -> 0.29907418 | L62: =IF(ISNUMBER(H62),IF(H62=0,"不适用（参考为0）",J62/H62),"") -> -0.14568318 | M62: =IF(ISNUMBER(L62),ABS(L62),L62) -> 0.14568318 | N62: 完整参考循环
A63: 28 | B63: =IF(COUNTIFS(参考循环数据!$A$7:$A$92,A63)>0,VLOOKUP(A63,参考循环数据!$A$7:$I$92,6,FALSE),"") -> 3.0512479 | C63: =MAX('0.02s时程'!G1757:G1822) -> 2.4062383 | D63: =IF(ISNUMBER(B63),C63-B63,"") -> -0.64500965 | E63: =IF(ISNUMBER(D63),ABS(D63),"") -> 0.64500965 | F63: =IF(ISNUMBER(B63),IF(B63=0,"不适用（参考为0）",D63/B63),"") -> -0.21139208 | G63: =IF(ISNUMBER(F63),ABS(F63),F63) -> 0.21139208 | H63: =IF(COUNTIFS(参考循环数据!$A$7:$A$92,A63)>0,VLOOKUP(A63,参考循环数据!$A$7:$I$92,5,FALSE),"") -> 2.0649146 | I63: =MIN('0.02s时程'!G1757:G1822) -> 1.7684706 | J63: =IF(ISNUMBER(H63),I63-H63,"") -> -0.29644399 | K63: =IF(ISNUMBER(J63),ABS(J63),"") -> 0.29644399 | L63: =IF(ISNUMBER(H63),IF(H63=0,"不适用（参考为0）",J63/H63),"") -> -0.14356235 | M63: =IF(ISNUMBER(L63),ABS(L63),L63) -> 0.14356235 | N63: 完整参考循环
A64: 29 | B64: =IF(COUNTIFS(参考循环数据!$A$7:$A$92,A64)>0,VLOOKUP(A64,参考循环数据!$A$7:$I$92,6,FALSE),"") -> 3.0635359 | C64: =MAX('0.02s时程'!G1822:G1887) -> 2.4198937 | D64: =IF(ISNUMBER(B64),C64-B64,"") -> -0.64364218 | E64: =IF(ISNUMBER(D64),ABS(D64),"") -> 0.64364218 | F64: =IF(ISNUMBER(B64),IF(B64=0,"不适用（参考为0）",D64/B64),"") -> -0.21009781 | G64: =IF(ISNUMBER(F64),ABS(F64),F64) -> 0.21009781 | H64: =IF(COUNTIFS(参考循环数据!$A$7:$A$92,A64)>0,VLOOKUP(A64,参考循环数据!$A$7:$I$92,5,FALSE),"") -> 2.0770999 | I64: =MIN('0.02s时程'!G1822:G1887) -> 1.7825326 | J64: =IF(ISNUMBER(H64),I64-H64,"") -> -0.29456727 | K64: =IF(ISNUMBER(J64),ABS(J64),"") -> 0.29456727 | L64: =IF(ISNUMBER(H64),IF(H64=0,"不适用（参考为0）",J64/H64),"") -> -0.14181661 | M64: =IF(ISNUMBER(L64),ABS(L64),L64) -> 0.14181661 | N64: 完整参考循环
...

Sheet 连续加载曲线
A2: 每0.02 s一个点的连续加载位移曲线
A4: 完整估算：0.20–130.20 s，共6501点。折线逐点连接，未只画峰谷包络，也未对曲线降采样。
A5: 估算沿用上一版数值；零时刻重复点已整理，详见“参考循环数据”的取样说明。
A31: 下图放大前5圈，叠加参考逐点曲线，便于区分每次加载和卸载。完整数据见“0.02s时程”。

Sheet 0.02s时程
A1: 样本序号 | B1: 时间 (s) | C1: 连续循环次数 | D1: 所属循环 | E1: 圈内相位 (s) | F1: 协议压力 (kPa) | G1: 估算位移 (mm) | H1: 估算压密项 (mm) | I1: 估算恢复项 (mm) | J1: 参考位移 (mm) | K1: 参考覆盖状态
A2: 0 | B2: 0.2 | C2: 0 | D2: 0 | E2: 0 | F2: 30 | G2: 0 | H2: 0 | I2: 0 | J2: 0 | K2: 有参考逐点数据
A3: 1 | B3: 0.22 | C3: 0.015384615 | D3: 1 | E3: 0.02 | F3: 38 | G3: 0.36514797 | H3: 0.0040960809 | I3: 0.36105189 | J3: 0.95984381 | K3: 有参考逐点数据
A4: 2 | B4: 0.24 | C4: 0.030769231 | D4: 1 | E4: 0.04 | F4: 46 | G4: 0.42511556 | H4: 0.011565113 | I4: 0.41355045 | J4: 1.1555638 | K4: 有参考逐点数据
A5: 3 | B5: 0.26 | C5: 0.046153846 | D5: 1 | E5: 0.06 | F5: 54 | G5: 0.48417297 | H5: 0.02119818 | I5: 0.46297479 | J5: 1.288042 | K5: 有参考逐点数据
A6: 4 | B6: 0.28 | C6: 0.061538462 | D6: 1 | E6: 0.08 | F6: 62 | G6: 0.54244475 | H6: 0.032548984 | I6: 0.50989577 | J6: 1.3933282 | K6: 有参考逐点数据
A7: 5 | B7: 0.3 | C7: 0.076923077 | D7: 1 | E7: 0.1 | F7: 70 | G7: 0.60007179 | H7: 0.04535002 | I7: 0.55472177 | J7: 1.4852239 | K7: 有参考逐点数据
A8: 6 | B8: 0.32 | C8: 0.092307692 | D8: 1 | E8: 0.12 | F8: 78 | G8: 0.65717136 | H8: 0.059413599 | I8: 0.59775776 | J8: 1.568328 | K8: 有参考逐点数据
A9: 7 | B9: 0.34 | C9: 0.10769231 | D9: 1 | E9: 0.14 | F9: 86 | G9: 0.71383528 | H9: 0.074596215 | I9: 0.63923906 | J9: 1.6454393 | K9: 有参考逐点数据
A10: 8 | B10: 0.36 | C10: 0.12307692 | D10: 1 | E10: 0.16 | F10: 94 | G10: 0.77013408 | H10: 0.090781981 | I10: 0.67935209 | J10: 1.7193537 | K10: 有参考逐点数据
A11: 9 | B11: 0.38 | C11: 0.13846154 | D11: 1 | E11: 0.18 | F11: 102 | G11: 0.8261214 | H11: 0.10787373 | I11: 0.71824767 | J11: 1.7899627 | K11: 有参考逐点数据
A12: 10 | B12: 0.4 | C12: 0.15384615 | D12: 1 | E12: 0.2 | F12: 110 | G12: 0.88183773 | H12: 0.12578771 | I12: 0.75605001 | J12: 1.8580994 | K12: 有参考逐点数据
A13: 11 | B13: 0.42 | C13: 0.16923077 | D13: 1 | E13: 0.22 | F13: 118 | G13: 0.93731322 | H13: 0.14445028 | I13: 0.79286293 | J13: 1.9239185 | K13: 有参考逐点数据
... A5612: 5610 | B5612: 112.4 | C5612: 86.307692 | D5612: 87 | E5612: 0.4 | F5612: 150 | G5612: 2.7959921 | H5612: 1.8641895 | I5612: 0.93180262 | J5612: 3.7433834 | K5612: 有参考逐点数据
A5613: 5611 | B5613: 112.42 | C5613: 86.323077 | D5613: 87 | E5613: 0.42 | F5613: 150 | G5613: 2.7961521 | H5613: 1.8643495 | I5613: 0.93180262 | K5613: 参考数据未导出
A5614: 5612 | B5614: 112.44 | C5614: 86.338462 | D5614: 87 | E5614: 0.44 | F5614: 150 | G5614: 2.7963119 | H5614: 1.8645093 | I5614: 0.93180262 | K5614: 参考数据未导出
A5615: 5613 | B5615: 112.46 | C5615: 86.353846 | D5615: 87 | E5615: 0.46 | F5615: 150 | G5615: 2.7964716 | H5615: 1.864669 | I5615: 0.93180262 | K5615: 参考数据未导出
A5616: 5614 | B5616: 112.48 | C5616: 86.369231 | D5616: 87 | E5616: 0.48 | F5616: 150 | G5616: 2.7966311 | H5616: 1.8648285 | I5616: 0.93180262 | K5616: 参考数据未导出
A5617: 5615 | B5617: 112.5 | C5617: 86.384615 | D5617: 87 | E5617: 0.5 | F5617: 150 | G5617: 2.7967905 | H5617: 1.8649879 | I5617: 0.93180262 | K5617: 参考数据未导出
A5618: 5616 | B5618: 112.52 | C5618: 86.4 | D5618: 87 | E5618: 0.52 | F5618: 142 | G5618: 2.7633201 | H5618: 1.8651368 | I5618: 0.89818332 | K5618: 参考数据未导出
A5619: 5617 | B5619: 112.54 | C5619: 86.415385 | D5619: 87 | E5619: 0.54 | F5619: 134 | G5619: 2.7291252 | H5619: 1.8652657 | I5619: 0.86385945 | K5619: 参考数据未导出
A5620: 5618 | B5620: 112.56 | C5620: 86.430769 | D5620: 87 | E5620: 0.56 | F5620: 126 | G5620: 2.6941505 | H5620: 1.8653762 | I5620: 0.82877434 | K5620: 参考数据未导出
A5621: 5619 | B5621: 112.58 | C5621: 86.446154 | D5621: 87 | E5621: 0.58 | F5621: 118 | G5621: 2.6583326 | H5621: 1.8654697 | I5621: 0.79286293 | K5621: 参考数据未导出
A5622: 5620 | B5622: 112.6 | C5622: 86.461538 | D5622: 87 | E5622: 0.6 | F5622: 110 | G5622: 2.6215976 | H5622: 1.8655476 | I5622: 0.75605001 | K5622: 参考数据未导出
A5623: 5621 | B5623: 112.62 | C5623: 86.476923 | D5623: 87 | E5623: 0.62 | F5623: 102 | G5623: 2.583859 | H5623: 1.8656113 | I5623: 0.71824767 | K5623: 参考数据未导出
A5624: 5622 | B5624: 112.64 | C5624: 86.492308 | D5624: 87 | E5624: 0.64 | F5624: 94 | G5624: 2.5450145 | H5624: 1.8656624 | I5624: 0.67935209 | K5624: 参考数据未导出
... A6502: 6500 | B6502: 130.2 | C6502: 100 | D6502: 100 | E6502: 1.3 | F6502: 30 | G6502: 2.2073716 | H6502: 1.9027383 | I6502: 0.30463327 | K6502: 参考数据未导出

Sheet 参考循环数据
A2: 参考文件循环汇总与比较口径
A4: 参考原表的数值快照；原文件未修改。第 1–86 圈完整，第 87 圈只有部分逐点记录。
A6: 循环次数 | B6: 起始时间 (s) | C6: 结束时间 (s) | D6: 循环起点位移 (mm) | E6: 循环最小位移 (mm) | F6: 循环最大位移 (mm) | G6: 循环位移范围 (mm) | H6: 循环终点累计位移 (mm) | I6: 终点位移增量 (mm/循环)
A7: 1 | B7: 0.2 | C7: 1.5 | D7: 0 | E7: 0 | F7: 2.2239786 | G7: 2.2239786 | H7: 1.3364279 | I7: 1.3364279
A8: 2 | B8: 1.5 | C8: 2.8 | D8: 1.3364279 | E8: 1.3364279 | F8: 2.3544004 | G8: 1.0179725 | H8: 1.4531613 | I8: 0.11673332
A9: 3 | B9: 2.8 | C9: 4.1 | D9: 1.4531613 | E9: 1.4531613 | F9: 2.4453973 | G9: 0.99223601 | H9: 1.5326778 | I9: 0.079516593
A10: 4 | B10: 4.1 | C10: 5.4 | D10: 1.5326778 | E10: 1.5326778 | F10: 2.5159427 | G10: 0.98326489 | H10: 1.5938789 | I10: 0.061201012
A11: 5 | B11: 5.4 | C11: 6.7 | D11: 1.5938789 | E11: 1.5938789 | F11: 2.5719775 | G11: 0.97809863 | H11: 1.6392043 | I11: 0.045325456
A12: 6 | B12: 6.7 | C12: 8 | D12: 1.6392043 | E12: 1.6392043 | F12: 2.6149734 | G12: 0.97576908 | H12: 1.6762613 | I12: 0.037057006
A13: 7 | B13: 8 | C13: 9.3 | D13: 1.6762613 | E13: 1.6762613 | F13: 2.6534431 | G13: 0.97718175 | H13: 1.7087247 | I13: 0.032463424
A14: 8 | B14: 9.3 | C14: 10.6 | D14: 1.7087247 | E14: 1.7087247 | F14: 2.6841355 | G14: 0.9754108 | H14: 1.7378688 | I14: 0.029144035
A15: 9 | B15: 10.6 | C15: 11.9 | D15: 1.7378688 | E15: 1.7378688 | F15: 2.7134724 | G15: 0.9756036 | H15: 1.7643067 | I15: 0.026437919
A16: 10 | B16: 11.9 | C16: 13.2 | D16: 1.7643067 | E16: 1.7643067 | F16: 2.7395907 | G16: 0.97528398 | H16: 1.7884987 | I16: 0.024192032
A17: 11 | B17: 13.2 | C17: 14.5 | D17: 1.7884987 | E17: 1.7884987 | F17: 2.7664592 | G17: 0.97796043 | H17: 1.8141852 | I17: 0.025686508
A18: 12 | B18: 14.5 | C18: 15.8 | D18: 1.8141852 | E18: 1.8141852 | F18: 2.7909798 | G18: 0.97679458 | H18: 1.8362418 | I18: 0.02205659
... A92: 86 | B92: 110.7 | C92: 112 | D92: 2.7008889 | E92: 2.7008889 | F92: 3.7308199 | G92: 1.029931 | H92: 2.7115542 | I92: 0.010665279
A96: 参考文件 | B96: [local source filename redacted]
A98: 参考数据范围 | B98: 循环汇总 A1:I87；逐点数据 A1:H5612。参考逐点数据截止 112.40 s。
A100: 原估算文件 | B100: [local source filename redacted]
A102: 参考 SHA-256 | B102: 309045fdf414eb9917e5529bdbe6f584813631cbaa4b253544acf4c5f5e54814
A104: 估算 SHA-256 | B104: 4213f867ede1b72c9ce242feb77c40ba626d6e267bc2f0c4b1b06f50b47b9355
A106: 位移定义 | B106: 两者均以 t=0.20 s 为零点，向下为正，单位 mm。估算没有用新参考数据重拟合。
A108: 波峰/波谷 | B108: 分别取每圈最大/最小位移，包含循环边界。波谷不等同于圈末 30 kPa 位移。
A110: 有符号误差 | B110: 相对误差 = (估算值 - 参考值) / 参考值。负值表示估算偏低。
A112: 绝对相对误差 | B112: 绝对相对误差 = |估算值 - 参考值| / |参考值|。MAPE 为有效循环该指标的算术平均。
A114: 零分母 | B114: 第1圈波谷参考值为0：百分比误差不适用。其绝对位移误差为0，仍计入MAE和RMSE。
A116: 缺失循环 | B116: 87–100圈无完整参考结果，误差留空。第87圈局部最大值不当作完整循环波峰。
A118: 严格等间距 | B118: 时程保留0.20 s加载前零点，删除同一时刻0.20 s+的重复估算点0.304633 mm；以后数值不变。
... A124: 校核限制 | B124: 已核对文件生成引擎、导出缓存值和原生图表结构；未调用桌面Excel执行原生重算。
